<?xml version="1.0"?>
<robot name="box_bot">
	<material name="red">
		<color rgba="1.0 0.0 0.0 1"/>
	</material>
	<material name="green_light">
		<color rgba="0.0 1.0 0.0 1"/>
	</material>
	<material name="green_dark">
		<color rgba="0.0 0.5 0.0 1"/>
	</material>
	<material name="blue">
		<color rgba="0.0 0.0 1.0 1"/>
	</material>
	<material name="cyan">
		<color rgba="0 1 1 1"/>
	</material>
	<material name="grey">
		<color rgba="0.5 0.5 0.5 1.0"/>
	</material>
	<material name="white">
		<color rgba="1.0 1.0 1.0 1"/>
	</material>
	<material name="box_bot_yellow">
		<color rgba="1.0 1.0 0.0 1"/>
	</material>
	<link name="base_link"></link>

					<!-- Body -->

	<link name="chassis">
		<visual>
			<geometry>
				<box size="0.2 0.1 0.1"/>
			</geometry>
			<material name="box_bot_yellow"/>
		</visual>
	</link>
	<joint name="base_link_joint" type="fixed">
		<origin rpy="0 0 0" xyz="0 0 0" />
		<parent link="base_link" />
		<child link="chassis" />
	</joint>
	
					<!-- Front Wheel Left -->
	
	<link name="front_left_wheel">
		<visual>
			<origin rpy="0 1.5707 1.5707" xyz="0.05 -0.025 -0.025"/>
			<geometry>
				<cylinder length="0.001" radius="0.0125"/>
			</geometry>
			<material name="grey"/>
		</visual>
	</link>
	<joint name="joint_front_left_wheel" type="continuous">
		<origin rpy="0 0 0" xyz="0.05 -0.025 -0.025"/>
		<child link="front_left_wheel"/>
		<parent link="chassis"/>
		<axis rpy="0 0 0" xyz="1 1 0"/>
		<limit effort="10000" velocity="1000"/>
		<joint_properties damping="1.0" friction="1.0"/>
	</joint>
	
					<!-- Back Wheel Left -->
	
	<link name="back_left_wheel">
		<visual>
			<origin rpy="0 1.5707 1.5707" xyz="-0.05 -0.025 -0.025"/>
			<geometry>
				<cylinder length="0.001" radius="0.0125"/>
			</geometry>
			<material name="grey"/>
		</visual>
	</link>
	<joint name="joint_back_left_wheel" type="continuous">
		<origin rpy="0 0 0" xyz="-0.05 -0.025 -0.025"/>
		<child link="back_left_wheel"/>
		<parent link="chassis"/>
		<axis rpy="0 0 0" xyz="0 1 0"/>
		<limit effort="10000" velocity="1000"/>
		<joint_properties damping="1.0" friction="1.0"/>
	</joint>
	
					<!-- Front Wheel Right -->
					
	<link name="front_right_wheel">
		<visual>
			<origin rpy="0 1.5707 1.5707" xyz="0.05 0.025 -0.025"/>
			<geometry>
				<cylinder length="0.001" radius="0.0125"/>
			</geometry>
			<material name="grey"/>
		</visual>
	</link>
	<joint name="joint_front_right_wheel" type="continuous">
		<origin rpy="0 0 0" xyz="0.05 0.025 -0.025"/>
		<child link="front_right_wheel"/>
		<parent link="chassis"/>
		<axis rpy="0 0 0" xyz="1 1 0"/>
		<limit effort="10000" velocity="1000"/>
		<joint_properties damping="1.0" friction="1.0"/>
	</joint>
	
					<!-- Back Wheel Right -->
					
	<link name="back_right_wheel">
		<visual>
			<origin rpy="0 1.5707 1.5707" xyz="-0.05 0.025 -0.025"/>
			<geometry>
				<cylinder length="0.001" radius="0.0125"/>
			</geometry>
			<material name="grey"/>
		</visual>
	</link>
	<joint name="joint_back_right_wheel" type="continuous">
		<origin rpy="0 0 0" xyz="-0.05 0.025 -0.025"/>
		<child link="back_right_wheel"/>
		<parent link="chassis"/>
		<axis rpy="0 0 0" xyz="0 1 0"/>
		<limit effort="10000" velocity="1000"/>
		<joint_properties damping="1.0" friction="1.0"/>
	</joint>
	
					<!-- Caster Wheel Front -->
					
	<link name="front_yaw_link">
		<visual>
			<origin rpy="0 1.5707 1.5707" xyz="0 0 0"/>
			<geometry>
				<cylinder length="0.005" radius="0.010"/>
			</geometry>
			<material name="blue"/>
		</visual>
	</link>
	<joint name="front_yaw_joint" type="continuous">
		<origin rpy="0 0 0" xyz="0.04 0 -0.05" />
		<parent link="chassis" />
		<child link="front_yaw_link" />
		<axis xyz="0 0 1" />
		<limit effort="1000.0" velocity="100.0" />
		<dynamics damping="0.0" friction="0.1"/>
	</joint>
	<link name="front_roll_link">
		<visual>
			<origin rpy="0 1.5707 1.5707" xyz="0 0 0"/>
			<geometry>
				<cylinder length="0.005" radius="0.010"/>
			</geometry>
			<material name="red"/>
		</visual>
	</link>
	<joint name="front_roll_joint" type="continuous">
		<origin rpy="0 0 0" xyz="0 0 0" />
		<parent link="front_yaw_link" />
		<child link="front_roll_link" />
		<axis xyz="1 0 0" />
		<limit effort="1000.0" velocity="100.0" />
		<dynamics damping="0.0" friction="0.1"/>
	</joint>
	<link name="front_pitch_link">
		<visual>
			<origin rpy="0 1.5707 1.5707" xyz="0 0 0"/>
			<geometry>
				<sphere radius="0.010"/>
			</geometry>
			<material name="green_dark"/>
		</visual>
	</link>
	<joint name="front_pitch_joint" type="continuous">
		<origin rpy="0 0 0" xyz="0 0 0" />
		<parent link="front_roll_link" />
		<child link="front_pitch_link" />
		<axis xyz="0 1 0" />
		<limit effort="1000.0" velocity="100.0" />
		<dynamics damping="0.0" friction="0.1"/>
	</joint>
	
					<!-- Caster Wheel Back -->
	
	<link name="back_yaw_link">
		<visual>
			<origin rpy="0 1.5707 1.5707" xyz="0 0 0"/>
			<geometry>
				<cylinder length="0.005" radius="0.010"/>
			</geometry>
			<material name="blue"/>
		</visual>
	</link>
	<joint name="back_yaw_joint" type="continuous">
		<origin rpy="0 0 0" xyz="-0.04 0 -0.05" />
		<parent link="chassis" />
		<child link="back_yaw_link" />
		<axis xyz="0 0 1" />
		<limit effort="1000.0" velocity="100.0" />
		<dynamics damping="0.0" friction="0.1"/>
	</joint>
	<link name="back_roll_link">
		<visual>
			<origin rpy="0 1.5707 1.5707" xyz="0 0 0"/>
			<geometry>
				<cylinder length="0.005" radius="0.010"/>
			</geometry>
			<material name="red"/>
		</visual>
	</link>
	<joint name="back_roll_joint" type="continuous">
		<origin rpy="0 0 0" xyz="0 0 0" />
		<parent link="back_yaw_link" />
		<child link="back_roll_link" />
		<axis xyz="1 0 0" />
		<limit effort="1000.0" velocity="100.0" />
		<dynamics damping="0.0" friction="0.1"/>
	</joint>
	<link name="back_pitch_link">
		<visual>
			<origin rpy="0 1.5707 1.5707" xyz="0 0 0"/>
			<geometry>
				<sphere radius="0.010"/>
			</geometry>
			<material name="green_dark"/>
		</visual>
	</link>
	<joint name="back_pitch_joint" type="continuous">
		<origin rpy="0 0 0" xyz="0 0 0" />
		<parent link="back_roll_link" />
		<child link="back_pitch_link" />
		<axis xyz="0 1 0" />
		<limit effort="1000.0" velocity="100.0" />
		<dynamics damping="0.0" friction="0.1"/>
	</joint>
</robot>
