<?xml version="1.0" encoding="UTF-8"?>
<robot name="box_bot">
	<material name="red">
		<color rgba="1.0 0.0 0.0 1.0"/>
	</material>
	<material name="green_light">
		<color rgba="0.56 1.0 0.56 1.0"/>
	</material>
	<material name="green_dark">
		<color rgba="0 0.5 0.0 1.0"/>
	</material>
	<material name="blue">
		<color rgba="0.0 0.0 1.0 1.0"/>
	</material>
	<material name="cyan">
		<color rgba="0.0 1.0 1.0 1.0"/>
	</material>
	<material name="grey">
		<color rgba="0.5 0.5 0.5 1.0"/>
	</material>
	<material name="white">
		<color rgba="1.0 1.0 1.0 1.0"/>
	</material>
	<material name="box_bot_yellow">
		<color rgba="1.0 1.0 0.0 1.0"/>
	</material>
	<link name="base_link"></link>
	<!-- Body -->
	<link name="chassis">
		<visual>
			<geometry>
				<box size="0.2 0.1 0.1"/>
			</geometry>
			<material name="box_bot_yellow"/>
		</visual>
		<collision>
			<geometry>
				<box size="0.2 0.1 0.1"/>
			</geometry>
		</collision>
		<inertial>
			<mass value="0.5"/>
			<origin rpy="0 0 0" xyz="0 0 0"/>
			 <inertia ixx="0.0008333333333333335" ixy="0" ixz="0" iyy="0.0008333333333333335" iyz="0" izz="0.0008333333333333335" />
		</inertial>
	</link>
	<gazebo reference="chassis">
		<material>Gazebo/Yellow</material>
	</gazebo>
	<joint name="base_link_joint" type="fixed">
		<origin rpy="0 0 0" xyz="0 0 0" />
		<parent link="base_link" />
		<child link="chassis" />
	</joint>
	<!-- Front Wheel Left -->
	<link name="front_left_wheel">
		<visual>
			<origin rpy="0 1.5707 1.5707" xyz="0.05 -0.025 -0.025"/>
			<geometry>
				<cylinder length="0.001" radius="0.0125"/>
			</geometry>
			<material name="grey"/>
		</visual>
		<collision>
			<origin rpy="0 1.5707 1.5707" xyz="0.05 -0.025 -0.025" />
			<geometry>
				<cylinder length="0.001" radius="0.0125" />
			</geometry>
		</collision>
		<inertial>
			<origin rpy="0 1.5707 1.5707" xyz="0.05 -0.025 -0.025" />
			<mass value="0.05" />
			<inertia ixx="1.531666666666667e-05" ixy="0" ixz="0" iyy="1.531666666666667e-05" iyz="0" izz="3.0625000000000006e-05" />
		</inertial>
	</link>
	<gazebo reference="front_left_wheel">
		<kp>1000000000000000000000000000.0</kp>
		<kd>1000000000000000000000000000.0</kd>
		<mu1>10.0</mu1>
		<mu2>10.0</mu2>
		<material>Gazebo/Grey</material>
	</gazebo>
	<joint name="joint_front_left_wheel" type="continuous">
		<origin rpy="0 0 0" xyz="0.05 -0.025 -0.025"/>
		<child link="front_left_wheel"/>
		<parent link="chassis"/>
		<axis rpy="0 0 0" xyz="1 1 0"/>
		<limit effort="10000" velocity="1000"/>
		<joint_properties damping="1.0" friction="1.0"/>
	</joint>
	<!-- Back Wheel Left -->
	<link name="back_left_wheel">
		<visual>
			<origin rpy="0 1.5707 1.5707" xyz="-0.05 -0.025 -0.025"/>
			<geometry>
				<cylinder length="0.001" radius="0.0125"/>
			</geometry>
			<material name="grey"/>
		</visual>
		<collision>
			<origin rpy="0 1.5707 1.5707" xyz="-0.05 -0.025 -0.025" />
			<geometry>
				<cylinder length="0.001" radius="0.0125" />
			</geometry>
		</collision>
		<inertial>
			<origin rpy="0 1.5707 1.5707" xyz="-0.05 -0.025 -0.025" />
			<mass value="0.05" />
			<inertia ixx="1.531666666666667e-05" ixy="0" ixz="0" iyy="1.531666666666667e-05" iyz="0" izz="3.0625000000000006e-05" />
		</inertial>
	</link>
	<gazebo reference="back_left_wheel">
		<kp>1000000000000000000000000000.0</kp>
		<kd>1000000000000000000000000000.0</kd>
		<mu1>10.0</mu1>
		<mu2>10.0</mu2>
		<material>Gazebo/Grey</material>
	</gazebo>
	<joint name="joint_back_left_wheel" type="continuous">
		<origin rpy="0 0 0" xyz="-0.05 -0.025 -0.025"/>
		<child link="back_left_wheel"/>
		<parent link="chassis"/>
		<axis rpy="0 0 0" xyz="0 1 0"/>
		<limit effort="10000" velocity="1000"/>
		<joint_properties damping="1.0" friction="1.0"/>
	</joint>
	<!-- Front Wheel Right -->
	<link name="front_right_wheel">
		<visual>
			<origin rpy="0 1.5707 1.5707" xyz="0.05 0.025 -0.025"/>
			<geometry>
				<cylinder length="0.001" radius="0.0125"/>
			</geometry>
			<material name="grey"/>
		</visual>
		<collision>
			<origin rpy="0 1.5707 1.5707" xyz="0.05 0.025 -0.025" />
			<geometry>
				<cylinder length="0.001" radius="0.0125" />
			</geometry>
		</collision>
		<inertial>
			<origin rpy="0 1.5707 1.5707" xyz="0.05 0.025 -0.025" />
			<mass value="0.05" />
			<inertia ixx="1.531666666666667e-05" ixy="0" ixz="0" iyy="1.531666666666667e-05" iyz="0" izz="3.0625000000000006e-05" />
		</inertial>
	</link>
	<gazebo reference="front_right_wheel">
		<kp>1000000000000000000000000000.0</kp>
		<kd>1000000000000000000000000000.0</kd>
		<mu1>10.0</mu1>
		<mu2>10.0</mu2>
		<material>Gazebo/Grey</material>
	</gazebo>
	<joint name="joint_front_right_wheel" type="continuous">
		<origin rpy="0 0 0" xyz="0.05 0.025 -0.025"/>
		<child link="front_right_wheel"/>
		<parent link="chassis"/>
		<axis rpy="0 0 0" xyz="1 1 0"/>
		<limit effort="10000" velocity="1000"/>
		<joint_properties damping="1.0" friction="1.0"/>
	</joint>
	<!-- Back Wheel Right -->
	<link name="back_right_wheel">
		<visual>
			<origin rpy="0 1.5707 1.5707" xyz="-0.05 0.025 -0.025"/>
			<geometry>
				<cylinder length="0.001" radius="0.0125"/>
			</geometry>
			<material name="grey"/>
		</visual>
		<collision>
			<origin rpy="0 1.5707 1.5707" xyz="-0.05 0.025 -0.025" />
			<geometry>
				<cylinder length="0.001" radius="0.0125" />
			</geometry>
		</collision>
		<inertial>
			<origin rpy="0 1.5707 1.5707" xyz="-0.05 0.025 -0.025" />
			<mass value="0.05" />
			<inertia ixx="1.531666666666667e-05" ixy="0" ixz="0" iyy="1.531666666666667e-05" iyz="0" izz="3.0625000000000006e-05" />
		</inertial>
	</link>
	<gazebo reference="back_right_wheel">
		<kp>1000000000000000000000000000.0</kp>
		<kd>1000000000000000000000000000.0</kd>
		<mu1>10.0</mu1>
		<mu2>10.0</mu2>
		<material>Gazebo/Grey</material>
	</gazebo>
	<joint name="joint_back_right_wheel" type="continuous">
		<origin rpy="0 0 0" xyz="-0.05 0.025 -0.025"/>
		<child link="back_right_wheel"/>
		<parent link="chassis"/>
		<axis rpy="0 0 0" xyz="0 1 0"/>
		<limit effort="10000" velocity="1000"/>
		<joint_properties damping="1.0" friction="1.0"/>
	</joint>
	<!-- Caster Wheel Front -->
	<link name="front_yaw_link">
		<visual>
			<origin rpy="0 1.5707 1.5707" xyz="0 0 0"/>
			<geometry>
				<cylinder length="0.001" radius="0.0045000000000000005"/>
			</geometry>
			<material name="blue"/>
		</visual>
		<collision>
			<origin rpy="0 1.5707 1.5707" xyz="0 0 0" />
			<geometry>
				<cylinder length="0.001" radius="0.0045000000000000005" />
			</geometry>
		</collision>
		<inertial>
			<origin rpy="0 1.5707 1.5707" xyz="0 0 0" />
			<mass value="0.001" />
			<inertia ixx="5.145833333333334e-09" ixy="0" ixz="0" iyy="5.145833333333334e-09" iyz="0" izz="1.0125000000000003e-08" />
		</inertial>
	</link>
	<gazebo reference="front_yaw_link">
		<material>Gazebo/Blue</material>
	</gazebo>
	<joint name="front_yaw_joint" type="continuous">
		<origin rpy="0 0 0" xyz="0.04 0 -0.05" />
		<parent link="chassis" />
		<child link="front_yaw_link" />
		<axis xyz="0 0 1" />
		<limit effort="1000.0" velocity="100.0" />
		<dynamics damping="0.0" friction="0.1"/>
	</joint>
	<link name="front_roll_link">
		<visual>
			<origin rpy="0 1.5707 1.5707" xyz="0 0 0"/>
			<geometry>
				<cylinder length="0.001" radius="0.0045000000000000005"/>
			</geometry>
			<material name="red"/>
		</visual>
		<collision>
			<origin rpy="0 1.5707 1.5707" xyz="0 0 0" />
			<geometry>
				<cylinder length="0.001" radius="0.0045000000000000005" />
			</geometry>
		</collision>
		<inertial>
			<origin rpy="0 1.5707 1.5707" xyz="0 0 0" />
			<mass value="0.001" />
			 <inertia ixx="5.145833333333334e-09" ixy="0" ixz="0" iyy="5.145833333333334e-09" iyz="0" izz="1.0125000000000003e-08" />
		</inertial>
	</link>
	<gazebo reference="front_roll_link">
		<material>Gazebo/Red</material>
	</gazebo>
	<joint name="front_roll_joint" type="continuous">
		<origin rpy="0 0 0" xyz="0 0 0" />
		<parent link="front_yaw_link" />
		<child link="front_roll_link" />
		<axis xyz="1 0 0" />
		<limit effort="1000.0" velocity="100.0" />
		<dynamics damping="0.0" friction="0.1"/>
	</joint>
	<link name="front_pitch_link">
		<visual>
			<origin rpy="0 1.5707 1.5707" xyz="0 0 0"/>
			<geometry>
				<sphere radius="0.010"/>
			</geometry>
			<material name="green_dark"/>
		</visual>
		<collision>
			<origin rpy="0 1.5707 1.5707" xyz="0 0 0" />
			<geometry>
				<sphere radius="0.010" />
			</geometry>
		</collision>
		<inertial>
			<origin rpy="0 1.5707 1.5707" xyz="0 0 0" />
			<mass value="0.001" />
			  <inertia ixx="4e-08" ixy="0" ixz="0" iyy="4e-08" iyz="0" izz="4e-08" />
		</inertial>
	</link>
	<gazebo reference="front_pitch_link">
		<kp>1000000000000000000000000000.0</kp>
		<kd>1000000000000000000000000000.0</kd>
		<mu1>0.5</mu1>
		<mu2>0.5</mu2>
		<material>Gazebo/Yellow</material>
	</gazebo>
	<joint name="front_pitch_joint" type="continuous">
		<origin rpy="0 0 0" xyz="0 0 0" />
		<parent link="front_roll_link" />
		<child link="front_pitch_link" />
		<axis xyz="0 1 0" />
		<limit effort="1000.0" velocity="100.0" />
		<dynamics damping="0.0" friction="0.1"/>
	</joint>
	<!-- Caster Wheel Back -->
	<link name="back_yaw_link">
		<visual>
			<origin rpy="0 1.5707 1.5707" xyz="0 0 0"/>
			<geometry>
				<cylinder length="0.001" radius="0.0045000000000000005"/>
			</geometry>
			<material name="blue"/>
		</visual>
		<collision>
			<origin rpy="0 1.5707 1.5707" xyz="0 0 0" />
			<geometry>
				<cylinder length="0.001" radius="0.0045000000000000005" />
			</geometry>
		</collision>
		<inertial>
			<origin rpy="0 1.5707 1.5707" xyz="0 0 0" />
			<mass value="0.001" />
			 <inertia ixx="5.145833333333334e-09" ixy="0" ixz="0" iyy="5.145833333333334e-09" iyz="0" izz="1.0125000000000003e-08" />
		</inertial>
	</link>
	<gazebo reference="back_yaw_link">
		<material>Gazebo/Blue</material>
	</gazebo>
	<joint name="back_yaw_joint" type="continuous">
		<origin rpy="0 0 0" xyz="-0.04 0 -0.05" />
		<parent link="chassis" />
		<child link="back_yaw_link" />
		<axis xyz="0 0 1" />
		<limit effort="1000.0" velocity="100.0" />
		<dynamics damping="0.0" friction="0.1"/>
	</joint>
	<link name="back_roll_link">
		<visual>
			<origin rpy="0 1.5707 1.5707" xyz="0 0 0"/>
			<geometry>
				<cylinder length="0.001" radius="0.0045000000000000005"/>
			</geometry>
			<material name="red"/>
		</visual>
		<collision>
			<origin rpy="0 1.5707 1.5707" xyz="0 0 0" />
			<geometry>
				<cylinder length="0.001" radius="0.0045000000000000005" />
			</geometry>
		</collision>
		<inertial>
			<origin rpy="0 1.5707 1.5707" xyz="0 0 0" />
			<mass value="0.001" />
			<inertia ixx="5.145833333333334e-09" ixy="0" ixz="0" iyy="5.145833333333334e-09" iyz="0" izz="1.0125000000000003e-08" />
		</inertial>
	</link>
	<gazebo reference="back_roll_link">
		<material>Gazebo/Red</material>
	</gazebo>
	<joint name="back_roll_joint" type="continuous">
		<origin rpy="0 0 0" xyz="0 0 0" />
		<parent link="back_yaw_link" />
		<child link="back_roll_link" />
		<axis xyz="1 0 0" />
		<limit effort="1000.0" velocity="100.0" />
		<dynamics damping="0.0" friction="0.1"/>
	</joint>
	<link name="back_pitch_link">
		<visual>
			<origin rpy="0 1.5707 1.5707" xyz="0 0 0"/>
			<geometry>
				<sphere radius="0.010"/>
			</geometry>
			<material name="green_dark"/>
		</visual>
		<collision>
			<origin rpy="0 1.5707 1.5707" xyz="0 0 0" />
			<geometry>
				<sphere radius="0.010" />
			</geometry>
		</collision>
		<inertial>
			<origin rpy="0 1.5707 1.5707" xyz="0 0 0" />
			<mass value="0.001" />
			<inertia ixx="4e-08" ixy="0" ixz="0" iyy="4e-08" iyz="0" izz="4e-08" />
		</inertial>
	</link>
	<gazebo reference="back_pitch_link">
		<kp>1000000000000000000000000000.0</kp>
		<kd>1000000000000000000000000000.0</kd>
		<mu1>0.5</mu1>
		<mu2>0.5</mu2>
		<material>Gazebo/Yellow</material>
	</gazebo>
	<joint name="back_pitch_joint" type="continuous">
		<origin rpy="0 0 0" xyz="0 0 0" />
		<parent link="back_roll_link" />
		<child link="back_pitch_link" />
		<axis xyz="0 1 0" />
		<limit effort="1000.0" velocity="100.0" />
		<dynamics damping="0.0" friction="0.1"/>
	</joint>
	<!-- Pole -->
	<link name="pole_link">
		<visual>
			<origin rpy="0 0 0" xyz="3 0 0" />
			<geometry>
				<cylinder length="0.3" radius="0.05" />
			</geometry>
			<material name="red"/>
		</visual>
		<collision>
			<origin rpy="0 0 0" xyz="3 0 0" />
			<geometry>
				<cylinder length="0.3" radius="0.05" />
			</geometry>
		</collision>
		<inertial>
			<origin rpy="0 0 0" xyz="3 0 0" />
			<mass value="0.001" />
			<inertia ixx="5.145833333333334e-09" ixy="0" ixz="0" iyy="5.145833333333334e-09" iyz="0" izz="1.0125000000000003e-08" />
		</inertial>
	</link>
	<gazebo reference="pole_link">
		<kp>1000000000000000000000000000.0</kp>
		<kd>1000000000000000000000000000.0</kd>
		<mu1>10.0</mu1>
		<mu2>10.0</mu2>
		<material>Gazebo/Red</material>
	</gazebo>
	<joint name="pole_joint" type="fixed">
		<origin rpy="0 0 0" xyz="0 0 0" />
		<parent link="base_link" />
		<child link="pole_link" />
		<axis xyz="1 0 0" />
		<limit effort="1000.0" velocity="100.0" />
		<dynamics damping="0.000000001" friction="0.1" />
	</joint>
	<!-- Laser Scan -->
	<link name="laser_scan_link">
		<visual>
			<origin rpy="0 0 0" xyz="0 0 0.0"/>
			<geometry>
				<cylinder length="0.04" radius="0.008" />
			</geometry>
			<material name="green_dark"/>
		</visual>
		<collision>
			<origin rpy="0 0 0" xyz="0 0 0.07"/>
			<geometry>
				<cylinder length="0.04" radius="0.008" />
			</geometry>
		</collision>
		<inertial>
			<mass value="0.01"/>
			<origin rpy="0 0 0" xyz="0 0 0.07"/>
			 <inertia ixx="6.066578520833334e-06" ixy="0" ixz="0" iyy="6.072950163333333e-06" iyz="0" izz="9.365128684166666e-06" />
		</inertial>
	</link>
	<gazebo reference="laser_scan_link">
		<kp>1000000000000000000000000000.0</kp>
		<kd>1000000000000000000000000000.0</kd>
		<mu1>10.0</mu1>
		<mu2>10.0</mu2>
		<material>Gazebo/Green</material>
	</gazebo>
	<joint name="laser_scan_link_joint" type="prismatic">
		<origin rpy="0 0 0" xyz="0 0 0.07"/>
		<parent link="chassis"/>
		<child link="laser_scan_link"/>
		<axis xyz="0 0 1"/>
		<limit lower="-0.1" upper="0.0" effort="20.0" velocity="2.0"/>
		<dynamics damping="0.1" friction="1.0"/>
	</joint>
	<link name="laser_scan_frame"></link>
	<joint name="laser_scan_frame_joint" type="fixed">
		<origin rpy="0 0 0" xyz="0 0 0.07"/>
		<parent link="laser_scan_link"/>
		<child link="laser_scan_frame"/>
		<axis xyz="0 0 0"/>
	</joint>
	<!-- RGB CAMERA -->
	<link name="rgb_camera_link_frame">
		<visual>
			<origin rpy="0 0 0" xyz="0.045 0 0.03"/>
			<geometry>
				<box size="0.02 0.02 0.02"/>
			</geometry>
			<material name="blue"/>
		</visual>
		<collision>
			<origin rpy="0 0 0" xyz="0.045 0 0.03" />
			<geometry>
				<box size="0.02 0.02 0.02"/>
			</geometry>
		</collision>
		<inertial>
			<origin rpy="0 0 0" xyz="0.045 0 0.03" />
			<mass value="0.001" />
			<inertia ixx="5.145833333333334e-09" ixy="0" ixz="0" iyy="5.145833333333334e-09" iyz="0" izz="1.0125000000000003e-08" />
		</inertial>
	</link>
	<gazebo reference="rgb_camera_link_frame">
		<kp>1000000000000000000000000000.0</kp>
		<kd>1000000000000000000000000000.0</kd>
		<mu1>10.0</mu1>
		<mu2>10.0</mu2>
		<material>Gazebo/Blue</material>
	</gazebo>
	<joint name="rgb_camera_link_frame_joint" type="fixed">
		<origin rpy="0 0 0" xyz="0.045 0.0 0.03"/>
		<parent link="chassis" />
		<child link="rgb_camera_link_frame" />
		<axis xyz="0 0 0"/>
	</joint>
	<gazebo reference="rgb_camera_link_frame">
		<sensor name="camera" type="wideanglecamera">
			<camera>
				<horizontal_fov>6.283</horizontal_fov>
				<image>
					<width>320</width>
					<height>240</height>
				</image>
				<clip>
					<near>0.1</near>
					<far>100</far>
				</clip>
				<lens>
					<type>custom</type>
					<custom_function>
						<c1>1.05</c1>
						<c2>4</c2>
						<f>1.0</f>
						<fun>tan</fun>
					</custom_function>
					<scale_to_hfov>true</scale_to_hfov>
					<cutoff_angle>3.1415</cutoff_angle>
					<env_texture_size>512</env_texture_size>
				</lens>
				<always_on>1</always_on>
				<update_rate>30</update_rate>
			</camera>
			<plugin name="camera_controller" filename="libgazebo_ros_camera.so">
				<cameraName>rgb_camera</cameraName>
				<imageTopicName>image_raw</imageTopicName>
				<cameraInfoTopicName>camera_info</cameraInfoTopicName>
				<frameName>rgb_camera_link_frame</frameName>
				<hackBaseline>0.07</hackBaseline>
			</plugin>
		</sensor>
	</gazebo>
</robot>
